[2024-06-29T03:24:28.964+0000] {taskinstance.py:1159} INFO - Dependencies all met for dep_context=non-requeueable deps ti=<TaskInstance: kafka_spark_dag.kafka_data_stream scheduled__2024-06-28T03:03:54.717838+00:00 [queued]>
[2024-06-29T03:24:28.968+0000] {taskinstance.py:1159} INFO - Dependencies all met for dep_context=requeueable deps ti=<TaskInstance: kafka_spark_dag.kafka_data_stream scheduled__2024-06-28T03:03:54.717838+00:00 [queued]>
[2024-06-29T03:24:28.968+0000] {taskinstance.py:1361} INFO - Starting attempt 2 of 2
[2024-06-29T03:24:28.975+0000] {taskinstance.py:1382} INFO - Executing <Task(PythonOperator): kafka_data_stream> on 2024-06-28 03:03:54.717838+00:00
[2024-06-29T03:24:28.978+0000] {standard_task_runner.py:57} INFO - Started process 50580 to run task
[2024-06-29T03:24:28.981+0000] {standard_task_runner.py:84} INFO - Running: ['***', 'tasks', 'run', 'kafka_spark_dag', 'kafka_data_stream', 'scheduled__2024-06-28T03:03:54.717838+00:00', '--job-id', '212', '--raw', '--subdir', 'DAGS_FOLDER/dag_kafka_spark.py', '--cfg-path', '/tmp/tmp5sxrersk']
[2024-06-29T03:24:28.983+0000] {standard_task_runner.py:85} INFO - Job 212: Subtask kafka_data_stream
[2024-06-29T03:24:29.008+0000] {task_command.py:416} INFO - Running <TaskInstance: kafka_spark_dag.kafka_data_stream scheduled__2024-06-28T03:03:54.717838+00:00 [running]> on host cd176cdca805
[2024-06-29T03:24:29.043+0000] {taskinstance.py:1662} INFO - Exporting env vars: AIRFLOW_CTX_DAG_OWNER='***' AIRFLOW_CTX_DAG_ID='kafka_spark_dag' AIRFLOW_CTX_TASK_ID='kafka_data_stream' AIRFLOW_CTX_EXECUTION_DATE='2024-06-28T03:03:54.717838+00:00' AIRFLOW_CTX_TRY_NUMBER='2' AIRFLOW_CTX_DAG_RUN_ID='scheduled__2024-06-28T03:03:54.717838+00:00'
[2024-06-29T03:24:29.045+0000] {conn.py:380} INFO - <BrokerConnection node_id=bootstrap-0 host=kafka:9092 <connecting> [IPv4 ('172.19.0.3', 9092)]>: connecting to kafka:9092 [('172.19.0.3', 9092) IPv4]
[2024-06-29T03:24:29.045+0000] {conn.py:1205} INFO - Probing node bootstrap-0 broker version
[2024-06-29T03:24:29.046+0000] {conn.py:410} INFO - <BrokerConnection node_id=bootstrap-0 host=kafka:9092 <connecting> [IPv4 ('172.19.0.3', 9092)]>: Connection complete.
[2024-06-29T03:24:29.149+0000] {conn.py:1267} INFO - Broker version identified as 2.5.0
[2024-06-29T03:24:29.149+0000] {conn.py:1268} INFO - Set configuration api_version=(2, 5, 0) to skip auto check_version requests on startup
[2024-06-29T03:24:29.158+0000] {taskinstance.py:1937} ERROR - Task failed with exception
Traceback (most recent call last):
  File "/home/airflow/.local/lib/python3.8/site-packages/urllib3/connection.py", line 174, in _new_conn
    conn = connection.create_connection(
  File "/home/airflow/.local/lib/python3.8/site-packages/urllib3/util/connection.py", line 72, in create_connection
    for res in socket.getaddrinfo(host, port, family, socket.SOCK_STREAM):
  File "/usr/local/lib/python3.8/socket.py", line 918, in getaddrinfo
    for res in _socket.getaddrinfo(host, port, family, type, proto, flags):
socket.gaierror: [Errno -2] Name or service not known

During handling of the above exception, another exception occurred:

Traceback (most recent call last):
  File "/home/airflow/.local/lib/python3.8/site-packages/urllib3/connectionpool.py", line 715, in urlopen
    httplib_response = self._make_request(
  File "/home/airflow/.local/lib/python3.8/site-packages/urllib3/connectionpool.py", line 404, in _make_request
    self._validate_conn(conn)
  File "/home/airflow/.local/lib/python3.8/site-packages/urllib3/connectionpool.py", line 1058, in _validate_conn
    conn.connect()
  File "/home/airflow/.local/lib/python3.8/site-packages/urllib3/connection.py", line 363, in connect
    self.sock = conn = self._new_conn()
  File "/home/airflow/.local/lib/python3.8/site-packages/urllib3/connection.py", line 186, in _new_conn
    raise NewConnectionError(
urllib3.exceptions.NewConnectionError: <urllib3.connection.HTTPSConnection object at 0xffff63aed3a0>: Failed to establish a new connection: [Errno -2] Name or service not known

During handling of the above exception, another exception occurred:

Traceback (most recent call last):
  File "/home/airflow/.local/lib/python3.8/site-packages/requests/adapters.py", line 486, in send
    resp = conn.urlopen(
  File "/home/airflow/.local/lib/python3.8/site-packages/urllib3/connectionpool.py", line 799, in urlopen
    retries = retries.increment(
  File "/home/airflow/.local/lib/python3.8/site-packages/urllib3/util/retry.py", line 592, in increment
    raise MaxRetryError(_pool, url, error or ResponseError(cause))
urllib3.exceptions.MaxRetryError: HTTPSConnectionPool(host='newsapi.org', port=443): Max retries exceeded with url: /v2/top-headlines?country=us&apiKey=8baf43d621934e4298eb9132ff8f4cd5 (Caused by NewConnectionError('<urllib3.connection.HTTPSConnection object at 0xffff63aed3a0>: Failed to establish a new connection: [Errno -2] Name or service not known'))

During handling of the above exception, another exception occurred:

Traceback (most recent call last):
  File "/home/airflow/.local/lib/python3.8/site-packages/airflow/operators/python.py", line 192, in execute
    return_value = self.execute_callable()
  File "/home/airflow/.local/lib/python3.8/site-packages/airflow/operators/python.py", line 209, in execute_callable
    return self.python_callable(*self.op_args, **self.op_kwargs)
  File "/opt/airflow/dags/src/kafka_client/kafka_stream_data.py", line 124, in stream
    results = query_data()
  File "/opt/airflow/dags/src/kafka_client/kafka_stream_data.py", line 90, in query_data
    full_data = get_all_data(last_processed)
  File "/opt/airflow/dags/src/kafka_client/kafka_stream_data.py", line 57, in get_all_data
    response = requests.get(url)
  File "/home/airflow/.local/lib/python3.8/site-packages/requests/api.py", line 73, in get
    return request("get", url, params=params, **kwargs)
  File "/home/airflow/.local/lib/python3.8/site-packages/requests/api.py", line 59, in request
    return session.request(method=method, url=url, **kwargs)
  File "/home/airflow/.local/lib/python3.8/site-packages/requests/sessions.py", line 589, in request
    resp = self.send(prep, **send_kwargs)
  File "/home/airflow/.local/lib/python3.8/site-packages/requests/sessions.py", line 703, in send
    r = adapter.send(request, **kwargs)
  File "/home/airflow/.local/lib/python3.8/site-packages/requests/adapters.py", line 519, in send
    raise ConnectionError(e, request=request)
requests.exceptions.ConnectionError: HTTPSConnectionPool(host='newsapi.org', port=443): Max retries exceeded with url: /v2/top-headlines?country=us&apiKey=8baf43d621934e4298eb9132ff8f4cd5 (Caused by NewConnectionError('<urllib3.connection.HTTPSConnection object at 0xffff63aed3a0>: Failed to establish a new connection: [Errno -2] Name or service not known'))
[2024-06-29T03:24:29.164+0000] {taskinstance.py:1400} INFO - Marking task as FAILED. dag_id=kafka_spark_dag, task_id=kafka_data_stream, execution_date=20240628T030354, start_date=20240629T032428, end_date=20240629T032429
[2024-06-29T03:24:29.170+0000] {standard_task_runner.py:104} ERROR - Failed to execute job 212 for task kafka_data_stream (HTTPSConnectionPool(host='newsapi.org', port=443): Max retries exceeded with url: /v2/top-headlines?country=us&apiKey=8baf43d621934e4298eb9132ff8f4cd5 (Caused by NewConnectionError('<urllib3.connection.HTTPSConnection object at 0xffff63aed3a0>: Failed to establish a new connection: [Errno -2] Name or service not known')); 50580)
[2024-06-29T03:24:29.204+0000] {local_task_job_runner.py:228} INFO - Task exited with return code 1
[2024-06-29T03:24:29.216+0000] {taskinstance.py:2778} INFO - 0 downstream tasks scheduled from follow-on schedule check
